2025-05-13 19:35:25.775 INFO __main__:start:262 - Starting Pet Data Ingestion service
2025-05-13 19:35:25.786 INFO __main__:load_pet_data:58 - Loaded 2 pet records
2025-05-13 19:35:25.788 INFO __main__:ingest:197 - Initial run - Last processed timestamp: 0
2025-05-13 19:35:25.788 ERROR __main__:ingest:252 - Error during initial ingestion: 'str' object has no attribute 'get'
2025-05-13 19:35:25.789 ERROR __main__:ingest:255 - Full traceback:
Traceback (most recent call last):

  File "src\data_ingrestion\data_ingrestion.py", line 302, in <module>
    asyncio.run(main())
    │       │   └ <function main at 0x000001CDBAE86D30>
    │       └ <function run at 0x000001CDBB2995E0>
    └ <module 'asyncio' from 'C:\\Users\\nguye\\miniconda3\\envs\\python_course\\lib\\asyncio\\__init__.py'>

  File "C:\Users\nguye\miniconda3\envs\python_course\lib\asyncio\runners.py", line 44, in run
    return loop.run_until_complete(main)
           │    │                  └ <coroutine object main at 0x000001CDDE7AC8C0>
           │    └ <function BaseEventLoop.run_until_complete at 0x000001CDBCE67D30>
           └ <ProactorEventLoop running=True closed=False debug=False>

  File "C:\Users\nguye\miniconda3\envs\python_course\lib\asyncio\base_events.py", line 603, in run_until_complete
    self.run_forever()
    │    └ <function ProactorEventLoop.run_forever at 0x000001CDBCF17160>
    └ <ProactorEventLoop running=True closed=False debug=False>

  File "C:\Users\nguye\miniconda3\envs\python_course\lib\asyncio\windows_events.py", line 316, in run_forever
    super().run_forever()

  File "C:\Users\nguye\miniconda3\envs\python_course\lib\asyncio\base_events.py", line 570, in run_forever
    self._run_once()
    │    └ <function BaseEventLoop._run_once at 0x000001CDBCE6B820>
    └ <ProactorEventLoop running=True closed=False debug=False>

  File "C:\Users\nguye\miniconda3\envs\python_course\lib\asyncio\base_events.py", line 1859, in _run_once
    handle._run()
    │      └ <function Handle._run at 0x000001CDBCDC2B80>
    └ <Handle <TaskWakeupMethWrapper object at 0x000001CDDE804D90>(<Future finished result=None>)>

  File "C:\Users\nguye\miniconda3\envs\python_course\lib\asyncio\events.py", line 81, in _run
    self._context.run(self._callback, *self._args)
    │    │            │    │           │    └ <member '_args' of 'Handle' objects>
    │    │            │    │           └ <Handle <TaskWakeupMethWrapper object at 0x000001CDDE804D90>(<Future finished result=None>)>
    │    │            │    └ <member '_callback' of 'Handle' objects>
    │    │            └ <Handle <TaskWakeupMethWrapper object at 0x000001CDDE804D90>(<Future finished result=None>)>
    │    └ <member '_context' of 'Handle' objects>
    └ <Handle <TaskWakeupMethWrapper object at 0x000001CDDE804D90>(<Future finished result=None>)>

  File "src\data_ingrestion\data_ingrestion.py", line 299, in main
    await service.start()
          │       └ <function DataIngrestion.start at 0x000001CDDE7C88B0>
          └ <__main__.DataIngrestion object at 0x000001CDDE7BD760>

  File "src\data_ingrestion\data_ingrestion.py", line 265, in start
    await self.ingest(is_initial_run=True)
          │    └ <function DataIngrestion.ingest at 0x000001CDDE7C8790>
          └ <__main__.DataIngrestion object at 0x000001CDDE7BD760>

> File "src\data_ingrestion\data_ingrestion.py", line 214, in ingest
    ads_list_from_entry = entry.get("ads")
                          └ 'total'

AttributeError: 'str' object has no attribute 'get'
